{
  "modified": "2025-06-26T16:49:31Z",
  "published": "2012-08-14T22:00:00Z",
  "schema_version": "1.5.0",
  "id": "CVE-2012-2135",
  "aliases": [
    "PSF-2012-6"
  ],
  "details": "The utf-16 decoder in Python 3.1 through 3.3 does not update the aligned_end variable after calling the unicode_decode_call_errorhandler function, which allows remote attackers to obtain sensitive information (process memory) or cause a denial of service (memory corruption and crash) via unspecified vectors.",
  "affected": [
    {
      "package": {
        "ecosystem": "DHI",
        "name": "python",
        "purl": "pkg:dhi/python"
      }
    }
  ],
  "references": [
    {
      "type": "REPORT",
      "url": "https://bugs.python.org/issue14579"
    }
  ]
}