{
  "modified": "2023-08-28T16:57:11Z",
  "published": "2023-08-24T00:00:00Z",
  "schema_version": "1.5.0",
  "id": "CVE-2022-48565",
  "aliases": [
    "PSF-2023-5",
    "GHSA-crhm-wc96-7579"
  ],
  "details": "An XML External Entity (XXE) issue was discovered in Python through 3.9.1. The plistlib module no longer accepts entity declarations in XML plist files to avoid XML vulnerabilities.",
  "affected": [
    {
      "package": {
        "ecosystem": "DHI",
        "name": "python",
        "purl": "pkg:dhi/python"
      },
      "ranges": [
        {
          "type": "SEMVER",
          "events": [
            {
              "introduced": "0"
            },
            {
              "fixed": "3.6.13"
            },
            {
              "introduced": "3.7.0-alpha1"
            },
            {
              "fixed": "3.7.10"
            },
            {
              "introduced": "3.8.0-alpha1"
            },
            {
              "fixed": "3.8.7-rc1"
            },
            {
              "introduced": "3.9.0-alpha1"
            },
            {
              "fixed": "3.9.1-rc1"
            },
            {
              "introduced": "3.10.0-alpha1"
            },
            {
              "fixed": "3.10.0-alpha2"
            }
          ],
          "repo": "https://github.com/python/cpython"
        }
      ]
    }
  ],
  "references": [
    {
      "type": "ADVISORY",
      "url": "https://nvd.nist.gov/vuln/detail/CVE-2022-48565"
    },
    {
      "type": "WEB",
      "url": "https://bugs.python.org/issue42051"
    }
  ]
}