{
  "modified": "2020-08-22T16:06:15Z",
  "published": "2019-03-23T17:07:08Z",
  "schema_version": "1.5.0",
  "id": "CVE-2019-9948",
  "aliases": [
    "PSF-2019-12"
  ],
  "details": "urllib in Python 2.x through 2.7.16 supports the local_file: scheme, which makes it easier for remote attackers to bypass protection mechanisms that blacklist file: URIs, as demonstrated by triggering a urllib.urlopen('local_file:///etc/passwd') call.",
  "affected": [
    {
      "package": {
        "ecosystem": "DHI",
        "name": "python",
        "purl": "pkg:dhi/python"
      },
      "severity": [
        {
          "type": "CVSS_V3",
          "score": "CVSS:3.1/AV:N/AC:L/PR:N/UI:N/S:U/C:H/I:H/A:N"
        }
      ],
      "ranges": [
        {
          "type": "SEMVER",
          "events": [
            {
              "introduced": "2.7.0"
            },
            {
              "fixed": "2.7.17"
            },
            {
              "introduced": "3.5.0"
            },
            {
              "fixed": "3.5.8"
            },
            {
              "introduced": "3.6.0"
            },
            {
              "fixed": "3.6.9"
            },
            {
              "introduced": "3.7.0"
            },
            {
              "fixed": "3.7.4"
            },
            {
              "fixed": "3.10.0-alpha1"
            },
            {
              "introduced": "3.10.0"
            }
          ],
          "repo": "https://github.com/python/cpython"
        }
      ]
    }
  ],
  "references": [
    {
      "type": "REPORT",
      "url": "https://bugs.python.org/issue35907"
    }
  ]
}