{
  "modified": "2017-09-18T12:57:01Z",
  "published": "2010-10-19T19:00:00Z",
  "schema_version": "1.5.0",
  "id": "CVE-2010-3492",
  "aliases": [
    "PSF-2010-6"
  ],
  "details": "The asyncore module in Python before 3.2 does not properly handle unsuccessful calls to the accept function, and does not have accompanying documentation describing how daemon applications should handle unsuccessful calls to the accept function, which makes it easier for remote attackers to conduct denial of service attacks that terminate these applications via network connections.",
  "affected": [
    {
      "package": {
        "ecosystem": "DHI",
        "name": "python",
        "purl": "pkg:dhi/python"
      },
      "ranges": [
        {
          "type": "SEMVER",
          "events": [
            {
              "fixed": "3.10.0-alpha1"
            },
            {
              "introduced": "3.10.0"
            },
            {},
            {}
          ],
          "repo": "https://github.com/python/cpython"
        }
      ]
    }
  ],
  "references": [
    {
      "type": "REPORT",
      "url": "https://bugs.python.org/issue6706"
    }
  ]
}