{
  "modified": "2023-08-25T16:05:33Z",
  "published": "2016-06-30T17:00:00Z",
  "schema_version": "1.5.0",
  "id": "CVE-2016-3189",
  "aliases": [
    "PSF-2016-5"
  ],
  "details": "Use-after-free vulnerability in bzip2recover in bzip2 1.0.6 allows remote attackers to cause a denial of service (crash) via a crafted bzip2 file, related to block ends set to before the start of the block.",
  "affected": [
    {
      "package": {
        "ecosystem": "DHI",
        "name": "python",
        "purl": "pkg:dhi/python"
      },
      "severity": [
        {
          "type": "CVSS_V3",
          "score": "CVSS:3.1/AV:N/AC:L/PR:N/UI:R/S:U/C:N/I:N/A:H"
        }
      ],
      "ranges": [
        {
          "type": "SEMVER",
          "events": [
            {
              "introduced": "3.7.0"
            },
            {
              "fixed": "3.7.13"
            },
            {
              "introduced": "3.8.0"
            },
            {
              "fixed": "3.8.13"
            },
            {
              "introduced": "3.9.0"
            },
            {
              "fixed": "3.9.11"
            },
            {
              "introduced": "3.10.0"
            },
            {
              "fixed": "3.10.3"
            }
          ],
          "repo": "https://github.com/python/cpython"
        }
      ]
    }
  ],
  "references": [
    {
      "type": "ADVISORY",
      "url": "https://access.redhat.com/security/cve/cve-2016-3189"
    },
    {
      "type": "ADVISORY",
      "url": "https://access.redhat.com/security/cve/cve-2019-12900"
    },
    {
      "type": "REPORT",
      "url": "https://bugs.python.org/issue44549"
    }
  ]
}