{
  "modified": "2023-08-28T16:57:11Z",
  "published": "2023-08-22T00:00:00Z",
  "schema_version": "1.5.0",
  "id": "CVE-2022-48560",
  "aliases": [
    "PSF-2023-11",
    "GHSA-pvw5-cvp6-cv92"
  ],
  "details": "A use-after-free exists in Python through 3.9 via heappushpop in heapq.",
  "affected": [
    {
      "package": {
        "ecosystem": "DHI",
        "name": "python",
        "purl": "pkg:dhi/python"
      },
      "severity": [
        {
          "type": "CVSS_V3",
          "score": "CVSS:3.1/AV:N/AC:L/PR:N/UI:N/S:U/C:N/I:N/A:H"
        }
      ],
      "ranges": [
        {
          "type": "SEMVER",
          "events": [
            {
              "introduced": "3.6.0"
            },
            {
              "fixed": "3.6.11"
            },
            {
              "introduced": "3.7.0"
            },
            {
              "fixed": "3.7.7"
            },
            {
              "introduced": "3.8.0"
            },
            {
              "fixed": "3.8.2"
            },
            {
              "fixed": "3.10.0-alpha1"
            },
            {
              "introduced": "3.10.0"
            }
          ],
          "repo": "https://github.com/python/cpython"
        }
      ]
    }
  ],
  "references": [
    {
      "type": "ADVISORY",
      "url": "https://www.cve.org/CVERecord?id=CVE-2022-48560"
    },
    {
      "type": "REPORT",
      "url": "https://bugs.python.org/issue39421"
    },
    {
      "type": "FIX",
      "url": "https://github.com/python/cpython/pull/18118"
    }
  ]
}